<?xml version="1.0"?>
<robot name="robot" xmlns:xacro="http://www.ros.org/wiki/xacro" xmlns:gz="http://gazebosim.org/schema">
  <material name="green">
    <color rgba="0.1686 1.0 0.2902 1.0"/>
  </material>
  <material name="black">
    <color rgba="0.3608 0.4510 0.6 1.0"/>
  </material>
  <material name="white">
    <color rgba="1 1 1 1.0"/>
  </material>

  <link name="base_link">
    <collision>
      <origin xyz="0 0 0.5" rpy="0 0 0"/>
      <geometry>
        <box size="2 1 0.5"/>
      </geometry>
    </collision>
    <visual>
      <origin xyz="0 0 0.5" rpy="0 0 0"/>
      <geometry>
        <box size="2 1 0.5"/>
      </geometry>
      <material name="green"/>
    </visual>
    <inertial>
      <origin xyz="0 -0 0.5" rpy="0 0 0"/>
      <mass value="1.5"/>
      <inertia
        ixx="0.13"
        ixy="0.0"
        ixz="0.0"
        iyy="0.42"
        iyz="0.0"
        izz="0.48"/>
    </inertial>
  </link>

  <joint name="front_left_wheel_joint" type="continuous">
    <origin xyz="0.6 0.5 0.3" rpy="-${pi/2} 0 0"/>
    <parent link="base_link"/>
    <child link="front_left_wheel"/>
    <axis xyz="0 0 1"/>
    <dynamics damping="0.2"/>
  </joint>
  <link name="front_left_wheel">
    <collision>
      <geometry>
        <sphere radius="0.3"/>
      </geometry>
    </collision>
    <visual>
      <geometry>
        <sphere radius="0.3"/>
      </geometry>
      <material name="black"/>
    </visual>
    <inertial>
      <mass value="2"/>
      <inertia ixx="0.145"
               ixy="0.0"
               ixz="0.0"
               iyy="0.145"
               iyz="0.0"
               izz="0.125"/>
    </inertial>
  </link>


  <joint name="front_right_wheel_joint" type="continuous">
    <origin xyz="0.6 -0.5 0.3" rpy="-${pi/2} 0 0"/>
    <parent link="base_link"/>
    <child link="front_right_wheel"/>
    <axis xyz="0 0 1"/>
    <dynamics damping="0.2"/>
  </joint>
  <link name="front_right_wheel">
    <collision>
      <geometry>
        <sphere radius="0.3"/>
      </geometry>
    </collision>
    <visual>
      <geometry>
        <sphere radius="0.3"/>
      </geometry>
      <material name="black"/>
    </visual>
    <inertial>
      <mass value="2"/>
      <inertia ixx="0.145"
               ixy="0.0"
               ixz="0.0"
               iyy="0.145"
               iyz="0.0"
               izz="0.125"/>
      </inertial>
  </link>


  <joint name="rear_left_wheel_joint" type="continuous">
    <origin xyz="-0.6 0.5 0.3" rpy="-${pi/2} 0 0"/>
    <parent link="base_link"/>
    <child link="rear_left_wheel"/>
    <axis xyz="0 0 1"/>
    <dynamics damping="0.2"/>
  </joint>
  <link name="rear_left_wheel">
    <collision>
      <geometry>
        <sphere radius="0.3"/>
      </geometry>
    </collision>
    <visual>
      <geometry>
        <sphere radius="0.3"/>
      </geometry>
      <material name="black"/>
    </visual>
    <inertial>
      <mass value="2"/>
      <inertia ixx="0.145"
               ixy="0.0"
               ixz="0.0"
               iyy="0.145"
               iyz="0.0"
               izz="0.125"/>
    </inertial>
  </link>

 
  <joint name="rear_right_wheel_joint" type="continuous">
    <origin xyz="-0.6 -0.5 0.3" rpy="-${pi/2} 0 0"/>
    <parent link="base_link"/>
    <child link="rear_right_wheel"/>
    <axis xyz="0 0 1"/>
    <dynamics damping="0.2"/>
  </joint>
  <link name="rear_right_wheel">
    <collision>
      <geometry>
        <sphere radius="0.3"/>
      </geometry>
    </collision>
    <visual>
      <geometry>
        <sphere radius="0.3"/>
      </geometry>
      <material name="black"/>
    </visual>
    <inertial>
      <mass value="2"/>
      <inertia ixx="0.145"
               ixy="0.0"
               ixz="0.0"
               iyy="0.145"
               iyz="0.0"
               izz="0.125"/>
      </inertial>
  </link>


  <gazebo reference='front_left_wheel'>
    <collision>
      <surface>
        <friction>
          <ode>
            <mu>1.0</mu>
            <mu2>0.0</mu2>
            <fdir1 gz:expressed_in="base_link">1 -1 0</fdir1>
          </ode>
        </friction>
      </surface>
    </collision>
  </gazebo>
  <gazebo reference='front_right_wheel'>
    <collision>
      <surface>
        <friction>
          <ode>
            <mu>1.0</mu>
            <mu2>0.0</mu2>
            <fdir1 gz:expressed_in="base_link">1 1 0</fdir1>
          </ode>
        </friction>
      </surface>
    </collision>
  </gazebo>
  <gazebo reference='rear_left_wheel'>
    <collision>
      <surface>
        <friction>
          <ode>
            <mu>1.0</mu>
            <mu2>0.0</mu2>
            <fdir1 gz:expressed_in="base_link">1 1 0</fdir1>
          </ode>
        </friction>
      </surface>
    </collision>
  </gazebo>
  <gazebo reference='rear_right_wheel'>
    <collision>
      <surface>
        <friction>
          <ode>
            <mu>1.0</mu>
            <mu2>0.0</mu2>
            <fdir1 gz:expressed_in="base_link">1 -1 0</fdir1>
          </ode>
        </friction>
      </surface>
    </collision>
  </gazebo>


  <ros2_control name="GazeboSimSystem" type="system">
    <hardware>
      <plugin>gz_ros2_control/GazeboSimSystem</plugin>
    </hardware>
    <joint name="front_left_wheel_joint">
      <command_interface name="velocity">
        <param name="min">-1</param>
        <param name="max">1</param>
      </command_interface>
      <state_interface name="position"/>
      <state_interface name="velocity"/>
    </joint>
    <joint name="front_right_wheel_joint">
      <command_interface name="velocity">
        <param name="min">-1</param>
        <param name="max">1</param>
      </command_interface>
      <state_interface name="position"/>
      <state_interface name="velocity"/>
    </joint>
    <joint name="rear_left_wheel_joint">
      <command_interface name="velocity">
        <param name="min">-1</param>
        <param name="max">1</param>
      </command_interface>
      <state_interface name="position"/>
      <state_interface name="velocity"/>
    </joint>
    <joint name="rear_right_wheel_joint">
      <command_interface name="velocity">
        <param name="min">-1</param>
        <param name="max">1</param>
      </command_interface>
      <state_interface name="position"/>
      <state_interface name="velocity"/>
    </joint>
  </ros2_control>

  <gazebo>
    <plugin filename="gz_ros2_control-system" name="gz_ros2_control::GazeboSimROS2ControlPlugin">
      <parameters>$(find robot_control)/config/drive_controller.yaml</parameters>
      <ros>
        <remapping>/drive_controller/reference:=/cmd_vel</remapping>
        <remapping>/drive_controller/odom:=/odom</remapping>
      </ros>
    </plugin>
  </gazebo>

</robot>
